<sdf version='1.6'>
  <world name='default'>
    <plugin name='ros_link_attacher_plugin' filename='libgazebo_ros_link_attacher.so'/>
    <model name='ground_plane'>
      <static>1</static>
      <link name='link'>
        <collision name='collision'>
          <geometry>
            <plane>
              <normal>0 0 1</normal>
              <size>100 100</size>
            </plane>
          </geometry>
          <surface>
            <friction>
              <ode>
                <mu>100</mu>
                <mu2>50</mu2>
              </ode>
              <torsional>
                <ode/>
              </torsional>
            </friction>
            <contact>
              <ode/>
            </contact>
            <bounce/>
          </surface>
          <max_contacts>10</max_contacts>
        </collision>
        <visual name='visual'>
          <cast_shadows>0</cast_shadows>
          <geometry>
            <plane>
              <normal>0 0 1</normal>
              <size>100 100</size>
            </plane>
          </geometry>
          <material>
            <script>
              <uri>file://media/materials/scripts/gazebo.material</uri>
              <name>Gazebo/Grey</name>
            </script>
          </material>
        </visual>
        <self_collide>0</self_collide>
        <kinematic>0</kinematic>
        <gravity>1</gravity>
      </link>
    </model>
    <light name='sun' type='directional'>
      <cast_shadows>1</cast_shadows>
      <pose frame=''>0 0 10 0 -0 0</pose>
      <diffuse>0.8 0.8 0.8 1</diffuse>
      <specular>0.1 0.1 0.1 1</specular>
      <attenuation>
        <range>1000</range>
        <constant>0.9</constant>
        <linear>0.01</linear>
        <quadratic>0.001</quadratic>
      </attenuation>
      <direction>-0.5 0.5 -1</direction>
    </light>
    <gui fullscreen='0'>
      <camera name='user_camera'>
        <pose frame=''>1.99949 -1.1248 0.869114 0 0.079643 2.46419</pose>
        <view_controller>orbit</view_controller>
        <projection_type>perspective</projection_type>
      </camera>
    </gui>
    <gravity>0 0 -9.8</gravity>
    <magnetic_field>6e-06 2.3e-05 -4.2e-05</magnetic_field>
    <atmosphere type='adiabatic'/>
    <physics name='default_physics' default='0' type='ode'>
      <max_step_size>0.001</max_step_size>
      <real_time_factor>1</real_time_factor>
      <real_time_update_rate>1000</real_time_update_rate>
    </physics>
    <scene>
      <ambient>0.4 0.4 0.4 1</ambient>
      <background>0.7 0.7 0.7 1</background>
      <shadows>1</shadows>
    </scene>
    <spherical_coordinates>
      <surface_model>EARTH_WGS84</surface_model>
      <latitude_deg>0</latitude_deg>
      <longitude_deg>0</longitude_deg>
      <elevation>0</elevation>
      <heading_deg>0</heading_deg>
    </spherical_coordinates>
    <state world_name='default'>
      <sim_time>88 595000000</sim_time>
      <real_time>12 330281919</real_time>
      <wall_time>1596012664 687595698</wall_time>
      <iterations>4703</iterations>
      <model name='box_1'>
        <pose frame=''>0.499863 -9e-06 0.199988 0 -0 4.9e-05</pose>
        <scale>1 1 1</scale>
        <link name='link'>
          <pose frame=''>0.499863 -9e-06 0.199988 0 -0 4.9e-05</pose>
          <velocity>0 0 0 0 -0 0</velocity>
          <acceleration>0.000811 0.000796 -11.5269 0.103374 -0.103994 1e-06</acceleration>
          <wrench>0.000811 0.000796 -11.5269 0 -0 0</wrench>
        </link>
      </model>
      <model name='box_2'>
        <pose frame=''>2e-06 0.499997 0.200001 2e-06 -3e-06 1.7e-05</pose>
        <scale>1 1 1</scale>
        <link name='link'>
          <pose frame=''>2e-06 0.499997 0.200001 2e-06 -3e-06 1.7e-05</pose>
          <velocity>0 0 0 0 -0 0</velocity>
          <acceleration>2.85971 1.4092 4.9326 2.27606 1.46084 -3.11674</acceleration>
          <wrench>2.85971 1.4092 4.9326 0 -0 0</wrench>
        </link>
      </model>
      <model name='ground_plane'>
        <pose frame=''>0 0 0 0 -0 0</pose>
        <scale>1 1 1</scale>
        <link name='link'>
          <pose frame=''>0 0 0 0 -0 0</pose>
          <velocity>0 0 0 0 -0 0</velocity>
          <acceleration>0 0 0 0 -0 0</acceleration>
          <wrench>0 0 0 0 -0 0</wrench>
        </link>
      </model>
      <model name='j2n6s300'>
        <pose frame=''>-1.3e-05 -1.8e-05 1e-06 -3.2e-05 1.9e-05 3e-06</pose>
        <scale>1 1 1</scale>
        <link name='j2n6s300_link_1'>
          <pose frame=''>-1.2e-05 -1.7e-05 0.156751 3.14154 1.7e-05 3.1415</pose>
          <velocity>-0.000439 -6e-05 0.000147 -0.000349 -0.003613 0.011152</velocity>
          <acceleration>-1.09571 0.352693 0.37695 -0.337323 0.803354 -0.29344</acceleration>
          <wrench>-0.819263 0.263708 0.281845 0 -0 0</wrench>
        </link>
        <link name='j2n6s300_link_2'>
          <pose frame=''>-1.5e-05 0.001576 0.275501 -1.57088 -0.24095 3.14153</pose>
          <velocity>-0.000884 -1.9e-05 0.000151 -0.000398 0.000434 0.01113</velocity>
          <acceleration>-0.897653 3.29526 0.052334 -2.05486 -1.39687 -0.299262</acceleration>
          <wrench>-0.888676 3.26231 0.051811 0 -0 0</wrench>
        </link>
        <link name='j2n6s300_link_3'>
          <pose frame=''>0.097822 0.001532 0.673657 -1.56791 1.53963 0.002812</pose>
          <velocity>-0.000704 0.001228 0.000107 -0.000407 0.012101 0.011105</velocity>
          <acceleration>1.16106 2.13643 2.13959 2.3258 -0.107638 2.9688</acceleration>
          <wrench>0.785226 1.44487 1.44701 0 -0 0</wrench>
        </link>
        <link name='j2n6s300_link_4'>
          <pose frame=''>-0.10938 -0.009852 0.667198 1.5351 0.508782 1.55333</pose>
          <velocity>-0.000506 -0.001201 0.002376 0.047396 0.012879 0.012155</velocity>
          <acceleration>1.16826 -3.78041 5.74644 2.22006 -1.11308 2.72926</acceleration>
          <wrench>0.498105 -1.61184 2.45009 0 -0 0</wrench>
        </link>
        <link name='j2n6s300_link_5'>
          <pose frame=''>-0.172483 -0.027893 0.632878 -0.618451 0.327642 -0.420947</pose>
          <velocity>-0.000668 -0.000416 0.002306 0.035092 0.001142 -0.00712</velocity>
          <acceleration>0.073364 -1.15963 1.96363 0.11731 -1.36386 2.27381</acceleration>
          <wrench>0.03128 -0.494429 0.837227 0 -0 0</wrench>
        </link>
        <link name='j2n6s300_link_6'>
          <pose frame=''>-0.209051 -0.085322 0.603725 1.66562 -0.327577 2.72066</pose>
          <velocity>-0.001133 0.000879 0.000345 0.001601 -0.078478 -0.000328</velocity>
          <acceleration>-1.53676 -0.839011 -1.47558 3.01994 0.474913 1.27256</acceleration>
          <wrench>-1.52139 -0.830621 -1.46082 0 -0 0</wrench>
        </link>
        <link name='j2n6s300_link_finger_1'>
          <pose frame=''>-0.244569 -0.191251 0.644368 -1.68807 -0.011685 -1.9703</pose>
          <velocity>-0.004554 0.000952 -0.002829 -0.198368 0.008648 0.016257</velocity>
          <acceleration>-6.83858 -1.14268 -16.5344 -1.25297 0.254462 -1.60056</acceleration>
          <wrench>-0.068386 -0.011427 -0.165345 0 -0 0</wrench>
        </link>
        <link name='j2n6s300_link_finger_2'>
          <pose frame=''>-0.280757 -0.181263 0.595663 1.05241 -0.15738 -1.92242</pose>
          <velocity>-0.00173 0.001239 -0.005459 0.036808 -0.101665 -0.049139</velocity>
          <acceleration>-8.48453 1.54496 -15.9927 1.81496 1.35194 3.13747</acceleration>
          <wrench>-0.084845 0.01545 -0.159927 0 -0 0</wrench>
        </link>
        <link name='j2n6s300_link_finger_3'>
          <pose frame=''>-0.242287 -0.198487 0.581341 1.42507 -0.166205 -1.94991</pose>
          <velocity>-0.001169 0.001534 -0.002435 1.20712 -0.589855 -0.169269</velocity>
          <acceleration>-18.1223 -5.89995 -75.9655 0.946224 -1.33009 1.60744</acceleration>
          <wrench>-0.181223 -0.059 -0.759655 0 -0 0</wrench>
        </link>
        <link name='j2n6s300_link_finger_tip_1'>
          <pose frame=''>-0.261346 -0.231888 0.647861 -1.71125 0.581065 -2.04916</pose>
          <velocity>-0.003845 0.001457 0.005224 -0.205706 0.00977 0.020131</velocity>
          <acceleration>-12.8548 -18.2525 -4.41651 -0.366839 -1.56946 2.97019</acceleration>
          <wrench>-0.128548 -0.182525 -0.044165 0 -0 0</wrench>
        </link>
        <link name='j2n6s300_link_finger_tip_2'>
          <pose frame=''>-0.297259 -0.221931 0.599987 1.01303 -0.391021 -1.77818</pose>
          <velocity>-0.00505 0.001753 -0.009226 -0.531788 0.170889 0.313975</velocity>
          <acceleration>5.52143 10.9698 1.49442 0.383437 0.422698 1.43867</acceleration>
          <wrench>0.055214 0.109698 0.014944 0 -0 0</wrench>
        </link>
        <link name='j2n6s300_link_finger_tip_3'>
          <pose frame=''>-0.258932 -0.239095 0.585693 1.42406 -0.202778 -1.94438</pose>
          <velocity>-0.011676 -0.000662 -0.0614 -2.85951 1.14142 0.431251</velocity>
          <acceleration>2.94229 18.6024 9.5162 -2.08174 0.011101 -0.288729</acceleration>
          <wrench>0.029423 0.186024 0.095162 0 -0 0</wrench>
        </link>
        <link name='root'>
          <pose frame=''>-1.3e-05 -1.8e-05 1e-06 -3.2e-05 1.9e-05 3e-06</pose>
          <velocity>0.000115 -0.000122 0.000139 -0.000466 -0.003564 0.005962</velocity>
          <acceleration>-0.693695 0.211321 0.371078 -1.90257 1.08937 -2.19844</acceleration>
          <wrench>-0.324538 0.098864 0.173605 0 -0 0</wrench>
        </link>
      </model>
      <model name='to_pickup'>
        <pose frame=''>0.499713 -6.3e-05 0.499989 3.8e-05 -3e-06 0.001909</pose>
        <scale>1 1 1</scale>
        <link name='link'>
          <pose frame=''>0.499713 -6.3e-05 0.499989 3.8e-05 -3e-06 0.001909</pose>
          <velocity>0 0 0 0 -0 0</velocity>
          <acceleration>0 0 0 0 -0 0</acceleration>
          <wrench>0 0 0 0 -0 0</wrench>
        </link>
      </model>
      <light name='sun'>
        <pose frame=''>0 0 10 0 -0 0</pose>
      </light>
    </state>
    <model name='j2n6s300'>
      <link name='root'>
        <pose frame=''>0 0 0 0 -0 0</pose>
        <inertial>
          <pose frame=''>0 0 0.1255 0 -0 0</pose>
          <mass>0.46784</mass>
          <inertia>
            <ixx>0.000951271</ixx>
            <ixy>0</ixy>
            <ixz>0</ixz>
            <iyy>0.000951271</iyy>
            <iyz>0</iyz>
            <izz>0.000374272</izz>
          </inertia>
        </inertial>
        <collision name='root_fixed_joint_lump__j2n6s300_link_base_collision'>
          <pose frame=''>0 0 0 0 -0 0</pose>
          <geometry>
            <mesh>
              <scale>1 1 1</scale>
              <uri>/home/brian/intern_ws/src/kinova-ros/kinova_description/meshes/base.dae</uri>
            </mesh>
          </geometry>
          <max_contacts>10</max_contacts>
          <surface>
            <contact>
              <ode/>
            </contact>
            <bounce/>
            <friction>
              <torsional>
                <ode/>
              </torsional>
              <ode/>
            </friction>
          </surface>
        </collision>
        <visual name='root_fixed_joint_lump__j2n6s300_link_base_visual'>
          <pose frame=''>0 0 0 0 -0 0</pose>
          <geometry>
            <mesh>
              <scale>1 1 1</scale>
              <uri>/home/brian/intern_ws/src/kinova-ros/kinova_description/meshes/base.dae</uri>
            </mesh>
          </geometry>
        </visual>
        <self_collide>0</self_collide>
        <kinematic>0</kinematic>
        <gravity>1</gravity>
      </link>
      <joint name='connect_root_and_world' type='revolute'>
        <child>root</child>
        <parent>world</parent>
        <axis>
          <limit>
            <lower>0</lower>
            <upper>0</upper>
          </limit>
          <dynamics>
            <damping>0</damping>
            <friction>0</friction>
            <spring_reference>0</spring_reference>
            <spring_stiffness>0</spring_stiffness>
          </dynamics>
          <use_parent_model_frame>1</use_parent_model_frame>
          <xyz>0 0 1</xyz>
        </axis>
      </joint>
      <link name='j2n6s300_link_1'>
        <pose frame=''>0 0 0.15675 3.14159 -0 3.14159</pose>
        <inertial>
          <pose frame=''>0 -0.002 -0.0605 0 -0 0</pose>
          <mass>0.7477</mass>
          <inertia>
            <ixx>0.00152032</ixx>
            <ixy>0</ixy>
            <ixz>0</ixz>
            <iyy>0.00152032</iyy>
            <iyz>0</iyz>
            <izz>0.00059816</izz>
          </inertia>
        </inertial>
        <collision name='j2n6s300_link_1_collision'>
          <pose frame=''>0 0 0 0 -0 0</pose>
          <geometry>
            <mesh>
              <scale>1 1 1</scale>
              <uri>/home/brian/intern_ws/src/kinova-ros/kinova_description/meshes/shoulder.dae</uri>
            </mesh>
          </geometry>
          <max_contacts>10</max_contacts>
          <surface>
            <contact>
              <ode/>
            </contact>
            <bounce/>
            <friction>
              <torsional>
                <ode/>
              </torsional>
              <ode/>
            </friction>
          </surface>
        </collision>
        <visual name='j2n6s300_link_1_visual'>
          <pose frame=''>0 0 0 0 -0 0</pose>
          <geometry>
            <mesh>
              <scale>1 1 1</scale>
              <uri>/home/brian/intern_ws/src/kinova-ros/kinova_description/meshes/shoulder.dae</uri>
            </mesh>
          </geometry>
        </visual>
        <visual name='j2n6s300_link_1_visual_1'>
          <pose frame=''>0 0 0 0 -0 0</pose>
          <geometry>
            <mesh>
              <scale>1 1 1</scale>
              <uri>/home/brian/intern_ws/src/kinova-ros/kinova_description/meshes/ring_big.dae</uri>
            </mesh>
          </geometry>
        </visual>
        <self_collide>0</self_collide>
        <kinematic>0</kinematic>
        <gravity>1</gravity>
      </link>
      <joint name='j2n6s300_joint_1' type='revolute'>
        <child>j2n6s300_link_1</child>
        <parent>root</parent>
        <axis>
          <xyz>0 0 -1</xyz>
          <limit>
            <lower>-1e+16</lower>
            <upper>1e+16</upper>
          </limit>
          <dynamics>
            <damping>0</damping>
            <friction>0</friction>
            <spring_reference>0</spring_reference>
            <spring_stiffness>0</spring_stiffness>
          </dynamics>
          <use_parent_model_frame>1</use_parent_model_frame>
        </axis>
        <physics>
          <provide_feedback>1</provide_feedback>
          <ode>
            <provide_feedback>1</provide_feedback>
            <limit>
              <cfm>0</cfm>
              <erp>0.2</erp>
            </limit>
          </ode>
        </physics>
      </joint>
      <link name='j2n6s300_link_2'>
        <pose frame=''>0 0.0016 0.2755 1.5708 -0 0</pose>
        <inertial>
          <pose frame=''>0 -0.2065 -0.01 0 -0 0</pose>
          <mass>0.99</mass>
          <inertia>
            <ixx>0.0105022</ixx>
            <ixy>0</ixy>
            <ixz>0</ixz>
            <iyy>0.000792</iyy>
            <iyz>0</iyz>
            <izz>0.0105022</izz>
          </inertia>
        </inertial>
        <collision name='j2n6s300_link_2_collision'>
          <pose frame=''>0 0 0 0 -0 0</pose>
          <geometry>
            <mesh>
              <scale>1 1 1</scale>
              <uri>/home/brian/intern_ws/src/kinova-ros/kinova_description/meshes/arm.dae</uri>
            </mesh>
          </geometry>
          <max_contacts>10</max_contacts>
          <surface>
            <contact>
              <ode/>
            </contact>
            <bounce/>
            <friction>
              <torsional>
                <ode/>
              </torsional>
              <ode/>
            </friction>
          </surface>
        </collision>
        <visual name='j2n6s300_link_2_visual'>
          <pose frame=''>0 0 0 0 -0 0</pose>
          <geometry>
            <mesh>
              <scale>1 1 1</scale>
              <uri>/home/brian/intern_ws/src/kinova-ros/kinova_description/meshes/arm.dae</uri>
            </mesh>
          </geometry>
        </visual>
        <visual name='j2n6s300_link_2_visual_1'>
          <pose frame=''>0 0 0 0 -0 0</pose>
          <geometry>
            <mesh>
              <scale>1 1 1</scale>
              <uri>/home/brian/intern_ws/src/kinova-ros/kinova_description/meshes/ring_big.dae</uri>
            </mesh>
          </geometry>
        </visual>
        <self_collide>0</self_collide>
        <kinematic>0</kinematic>
        <gravity>1</gravity>
      </link>
      <joint name='j2n6s300_joint_2' type='revolute'>
        <child>j2n6s300_link_2</child>
        <parent>j2n6s300_link_1</parent>
        <axis>
          <xyz>0 -1 0</xyz>
          <limit>
            <lower>0.820305</lower>
            <upper>5.46288</upper>
            <effort>80</effort>
            <velocity>0.628319</velocity>
          </limit>
          <dynamics>
            <damping>0</damping>
            <friction>0</friction>
            <spring_reference>0</spring_reference>
            <spring_stiffness>0</spring_stiffness>
          </dynamics>
          <use_parent_model_frame>1</use_parent_model_frame>
        </axis>
        <physics>
          <provide_feedback>1</provide_feedback>
          <ode>
            <provide_feedback>1</provide_feedback>
            <limit>
              <cfm>0</cfm>
              <erp>0.2</erp>
            </limit>
          </ode>
        </physics>
      </joint>
      <link name='j2n6s300_link_3'>
        <pose frame=''>-0 0.0016 -0.1345 1.5708 -0 3.14159</pose>
        <inertial>
          <pose frame=''>0 0.081 -0.0086 0 -0 0</pose>
          <mass>0.6763</mass>
          <inertia>
            <ixx>0.00142022</ixx>
            <ixy>0</ixy>
            <ixz>0</ixz>
            <iyy>0.000304335</iyy>
            <iyz>0</iyz>
            <izz>0.00142022</izz>
          </inertia>
        </inertial>
        <collision name='j2n6s300_link_3_collision'>
          <pose frame=''>0 0 0 0 -0 0</pose>
          <geometry>
            <mesh>
              <scale>1 1 1</scale>
              <uri>/home/brian/intern_ws/src/kinova-ros/kinova_description/meshes/forearm.dae</uri>
            </mesh>
          </geometry>
          <max_contacts>10</max_contacts>
          <surface>
            <contact>
              <ode/>
            </contact>
            <bounce/>
            <friction>
              <torsional>
                <ode/>
              </torsional>
              <ode/>
            </friction>
          </surface>
        </collision>
        <visual name='j2n6s300_link_3_visual'>
          <pose frame=''>0 0 0 0 -0 0</pose>
          <geometry>
            <mesh>
              <scale>1 1 1</scale>
              <uri>/home/brian/intern_ws/src/kinova-ros/kinova_description/meshes/forearm.dae</uri>
            </mesh>
          </geometry>
        </visual>
        <visual name='j2n6s300_link_3_visual_1'>
          <pose frame=''>0 0 0 0 -0 0</pose>
          <geometry>
            <mesh>
              <scale>1 1 1</scale>
              <uri>/home/brian/intern_ws/src/kinova-ros/kinova_description/meshes/ring_big.dae</uri>
            </mesh>
          </geometry>
        </visual>
        <self_collide>0</self_collide>
        <kinematic>0</kinematic>
        <gravity>1</gravity>
      </link>
      <joint name='j2n6s300_joint_3' type='revolute'>
        <child>j2n6s300_link_3</child>
        <parent>j2n6s300_link_2</parent>
        <axis>
          <xyz>0 1 0</xyz>
          <limit>
            <lower>0.331613</lower>
            <upper>5.95157</upper>
            <effort>40</effort>
            <velocity>0.628319</velocity>
          </limit>
          <dynamics>
            <damping>0</damping>
            <friction>0</friction>
            <spring_reference>0</spring_reference>
            <spring_stiffness>0</spring_stiffness>
          </dynamics>
          <use_parent_model_frame>1</use_parent_model_frame>
        </axis>
        <physics>
          <provide_feedback>1</provide_feedback>
          <ode>
            <provide_feedback>1</provide_feedback>
            <limit>
              <cfm>0</cfm>
              <erp>0.2</erp>
            </limit>
          </ode>
        </physics>
      </joint>
      <link name='j2n6s300_link_4'>
        <pose frame=''>-0 -0.0098 0.0728 -3.14159 0 0</pose>
        <inertial>
          <pose frame=''>0 -0.037 -0.0642 0 -0 0</pose>
          <mass>0.426367</mass>
          <inertia>
            <ixx>7.73497e-05</ixx>
            <ixy>0</ixy>
            <ixz>0</ixz>
            <iyy>7.73497e-05</iyy>
            <iyz>0</iyz>
            <izz>0.0001428</izz>
          </inertia>
        </inertial>
        <collision name='j2n6s300_link_4_collision'>
          <pose frame=''>0 0 0 0 -0 0</pose>
          <geometry>
            <mesh>
              <scale>1 1 1</scale>
              <uri>/home/brian/intern_ws/src/kinova-ros/kinova_description/meshes/wrist.dae</uri>
            </mesh>
          </geometry>
          <max_contacts>10</max_contacts>
          <surface>
            <contact>
              <ode/>
            </contact>
            <bounce/>
            <friction>
              <torsional>
                <ode/>
              </torsional>
              <ode/>
            </friction>
          </surface>
        </collision>
        <visual name='j2n6s300_link_4_visual'>
          <pose frame=''>0 0 0 0 -0 0</pose>
          <geometry>
            <mesh>
              <scale>1 1 1</scale>
              <uri>/home/brian/intern_ws/src/kinova-ros/kinova_description/meshes/wrist.dae</uri>
            </mesh>
          </geometry>
        </visual>
        <visual name='j2n6s300_link_4_visual_1'>
          <pose frame=''>0 0 0 0 -0 0</pose>
          <geometry>
            <mesh>
              <scale>1 1 1</scale>
              <uri>/home/brian/intern_ws/src/kinova-ros/kinova_description/meshes/ring_small.dae</uri>
            </mesh>
          </geometry>
        </visual>
        <self_collide>0</self_collide>
        <kinematic>0</kinematic>
        <gravity>1</gravity>
      </link>
      <joint name='j2n6s300_joint_4' type='revolute'>
        <child>j2n6s300_link_4</child>
        <parent>j2n6s300_link_3</parent>
        <axis>
          <xyz>0 0 -1</xyz>
          <limit>
            <lower>-1e+16</lower>
            <upper>1e+16</upper>
          </limit>
          <dynamics>
            <damping>0</damping>
            <friction>0</friction>
            <spring_reference>0</spring_reference>
            <spring_stiffness>0</spring_stiffness>
          </dynamics>
          <use_parent_model_frame>1</use_parent_model_frame>
        </axis>
        <physics>
          <provide_feedback>1</provide_feedback>
          <ode>
            <provide_feedback>1</provide_feedback>
            <limit>
              <cfm>0</cfm>
              <erp>0.2</erp>
            </limit>
          </ode>
        </physics>
      </joint>
      <link name='j2n6s300_link_5'>
        <pose frame=''>0 0.02723 0.13694 -2.0944 -0 3.14159</pose>
        <inertial>
          <pose frame=''>0 -0.037 -0.0642 0 -0 0</pose>
          <mass>0.426367</mass>
          <inertia>
            <ixx>7.73497e-05</ixx>
            <ixy>0</ixy>
            <ixz>0</ixz>
            <iyy>7.73497e-05</iyy>
            <iyz>0</iyz>
            <izz>0.0001428</izz>
          </inertia>
        </inertial>
        <collision name='j2n6s300_link_5_collision'>
          <pose frame=''>0 0 0 0 -0 0</pose>
          <geometry>
            <mesh>
              <scale>1 1 1</scale>
              <uri>/home/brian/intern_ws/src/kinova-ros/kinova_description/meshes/wrist.dae</uri>
            </mesh>
          </geometry>
          <max_contacts>10</max_contacts>
          <surface>
            <contact>
              <ode/>
            </contact>
            <bounce/>
            <friction>
              <torsional>
                <ode/>
              </torsional>
              <ode/>
            </friction>
          </surface>
        </collision>
        <visual name='j2n6s300_link_5_visual'>
          <pose frame=''>0 0 0 0 -0 0</pose>
          <geometry>
            <mesh>
              <scale>1 1 1</scale>
              <uri>/home/brian/intern_ws/src/kinova-ros/kinova_description/meshes/wrist.dae</uri>
            </mesh>
          </geometry>
        </visual>
        <visual name='j2n6s300_link_5_visual_1'>
          <pose frame=''>0 0 0 0 -0 0</pose>
          <geometry>
            <mesh>
              <scale>1 1 1</scale>
              <uri>/home/brian/intern_ws/src/kinova-ros/kinova_description/meshes/ring_small.dae</uri>
            </mesh>
          </geometry>
        </visual>
        <self_collide>0</self_collide>
        <kinematic>0</kinematic>
        <gravity>1</gravity>
      </link>
      <joint name='j2n6s300_joint_5' type='revolute'>
        <child>j2n6s300_link_5</child>
        <parent>j2n6s300_link_4</parent>
        <axis>
          <xyz>0 -0.866025 -0.5</xyz>
          <limit>
            <lower>-1e+16</lower>
            <upper>1e+16</upper>
          </limit>
          <dynamics>
            <damping>0</damping>
            <friction>0</friction>
            <spring_reference>0</spring_reference>
            <spring_stiffness>0</spring_stiffness>
          </dynamics>
          <use_parent_model_frame>1</use_parent_model_frame>
        </axis>
        <physics>
          <provide_feedback>1</provide_feedback>
          <ode>
            <provide_feedback>1</provide_feedback>
            <limit>
              <cfm>0</cfm>
              <erp>0.2</erp>
            </limit>
          </ode>
        </physics>
      </joint>
      <link name='j2n6s300_link_6'>
        <pose frame=''>0 0.064262 0.201079 -3.14159 0 0</pose>
        <inertial>
          <pose frame=''>0 0 -0.06 0 -0 0</pose>
          <mass>0.99</mass>
          <inertia>
            <ixx>0.000345324</ixx>
            <ixy>0</ixy>
            <ixz>0</ixz>
            <iyy>0.000345324</iyy>
            <iyz>0</iyz>
            <izz>0.0005816</izz>
          </inertia>
        </inertial>
        <collision name='j2n6s300_link_6_collision'>
          <pose frame=''>0 0 0 0 -0 0</pose>
          <geometry>
            <mesh>
              <scale>1 1 1</scale>
              <uri>/home/brian/intern_ws/src/kinova-ros/kinova_description/meshes/hand_3finger.dae</uri>
            </mesh>
          </geometry>
          <max_contacts>10</max_contacts>
          <surface>
            <contact>
              <ode/>
            </contact>
            <bounce/>
            <friction>
              <torsional>
                <ode/>
              </torsional>
              <ode/>
            </friction>
          </surface>
        </collision>
        <visual name='j2n6s300_link_6_visual'>
          <pose frame=''>0 0 0 0 -0 0</pose>
          <geometry>
            <mesh>
              <scale>1 1 1</scale>
              <uri>/home/brian/intern_ws/src/kinova-ros/kinova_description/meshes/hand_3finger.dae</uri>
            </mesh>
          </geometry>
        </visual>
        <visual name='j2n6s300_link_6_visual_1'>
          <pose frame=''>0 0 0 0 -0 0</pose>
          <geometry>
            <mesh>
              <scale>1 1 1</scale>
              <uri>/home/brian/intern_ws/src/kinova-ros/kinova_description/meshes/ring_small.dae</uri>
            </mesh>
          </geometry>
        </visual>
        <self_collide>0</self_collide>
        <kinematic>0</kinematic>
        <gravity>1</gravity>
      </link>
      <joint name='j2n6s300_joint_6' type='revolute'>
        <child>j2n6s300_link_6</child>
        <parent>j2n6s300_link_5</parent>
        <axis>
          <xyz>0 0 -1</xyz>
          <limit>
            <lower>-1e+16</lower>
            <upper>1e+16</upper>
          </limit>
          <dynamics>
            <damping>0</damping>
            <friction>0</friction>
            <spring_reference>0</spring_reference>
            <spring_stiffness>0</spring_stiffness>
          </dynamics>
          <use_parent_model_frame>1</use_parent_model_frame>
        </axis>
        <physics>
          <provide_feedback>1</provide_feedback>
          <ode>
            <provide_feedback>1</provide_feedback>
            <limit>
              <cfm>0</cfm>
              <erp>0.2</erp>
            </limit>
          </ode>
        </physics>
      </joint>
      <link name='j2n6s300_link_finger_1'>
        <pose frame=''>0.00279 0.033002 0.315749 1.5708 -0.649262 -1.35961</pose>
        <inertial>
          <pose frame=''>0.022 0 0 0 -0 0</pose>
          <mass>0.01</mass>
          <inertia>
            <ixx>7.89997e-07</ixx>
            <ixy>0</ixy>
            <ixz>0</ixz>
            <iyy>7.89997e-07</iyy>
            <iyz>0</iyz>
            <izz>8e-08</izz>
          </inertia>
        </inertial>
        <collision name='j2n6s300_link_finger_1_collision'>
          <pose frame=''>0 0 0 0 -0 0</pose>
          <geometry>
            <mesh>
              <scale>1 1 1</scale>
              <uri>/home/brian/intern_ws/src/kinova-ros/kinova_description/meshes/finger_proximal.dae</uri>
            </mesh>
          </geometry>
          <max_contacts>10</max_contacts>
          <surface>
            <contact>
              <ode/>
            </contact>
            <bounce/>
            <friction>
              <torsional>
                <ode/>
              </torsional>
              <ode/>
            </friction>
          </surface>
        </collision>
        <visual name='j2n6s300_link_finger_1_visual'>
          <pose frame=''>0 0 0 0 -0 0</pose>
          <geometry>
            <mesh>
              <scale>1 1 1</scale>
              <uri>/home/brian/intern_ws/src/kinova-ros/kinova_description/meshes/finger_proximal.dae</uri>
            </mesh>
          </geometry>
        </visual>
        <self_collide>0</self_collide>
        <kinematic>0</kinematic>
        <gravity>1</gravity>
      </link>
      <joint name='j2n6s300_joint_finger_1' type='revolute'>
        <child>j2n6s300_link_finger_1</child>
        <parent>j2n6s300_link_6</parent>
        <axis>
          <xyz>-0.977783 -0.209619 0</xyz>
          <limit>
            <lower>0</lower>
            <upper>1.51</upper>
            <effort>2</effort>
            <velocity>1</velocity>
          </limit>
          <dynamics>
            <spring_reference>0</spring_reference>
            <spring_stiffness>0</spring_stiffness>
          </dynamics>
          <use_parent_model_frame>1</use_parent_model_frame>
        </axis>
      </joint>
      <link name='j2n6s300_link_finger_tip_1'>
        <pose frame=''>0.010517 -0.00304 0.339962 1.5708 -0.649262 -1.35961</pose>
        <inertial>
          <pose frame=''>0.022 0 0 0 -0 0</pose>
          <mass>0.01</mass>
          <inertia>
            <ixx>7.89997e-07</ixx>
            <ixy>0</ixy>
            <ixz>0</ixz>
            <iyy>7.89997e-07</iyy>
            <iyz>0</iyz>
            <izz>8e-08</izz>
          </inertia>
        </inertial>
        <collision name='j2n6s300_link_finger_tip_1_collision'>
          <pose frame=''>0 0 0 0 -0 0</pose>
          <geometry>
            <mesh>
              <scale>1 1 1</scale>
              <uri>/home/brian/intern_ws/src/kinova-ros/kinova_description/meshes/finger_distal.dae</uri>
            </mesh>
          </geometry>
          <max_contacts>10</max_contacts>
          <surface>
            <contact>
              <ode/>
            </contact>
            <bounce/>
            <friction>
              <torsional>
                <ode/>
              </torsional>
              <ode/>
            </friction>
          </surface>
        </collision>
        <visual name='j2n6s300_link_finger_tip_1_visual'>
          <pose frame=''>0 0 0 0 -0 0</pose>
          <geometry>
            <mesh>
              <scale>1 1 1</scale>
              <uri>/home/brian/intern_ws/src/kinova-ros/kinova_description/meshes/finger_distal.dae</uri>
            </mesh>
          </geometry>
        </visual>
        <self_collide>0</self_collide>
        <kinematic>0</kinematic>
        <gravity>1</gravity>
      </link>
      <joint name='j2n6s300_joint_finger_tip_1' type='revolute'>
        <child>j2n6s300_link_finger_tip_1</child>
        <parent>j2n6s300_link_finger_1</parent>
        <axis>
          <xyz>-0.977783 -0.209619 0</xyz>
          <limit>
            <lower>0</lower>
            <upper>2</upper>
            <effort>2</effort>
            <velocity>1</velocity>
          </limit>
          <dynamics>
            <spring_reference>0</spring_reference>
            <spring_stiffness>0</spring_stiffness>
          </dynamics>
          <use_parent_model_frame>1</use_parent_model_frame>
        </axis>
      </joint>
      <link name='j2n6s300_link_finger_2'>
        <pose frame=''>0.02226 0.091332 0.315899 1.5708 -0.649262 1.38614</pose>
        <inertial>
          <pose frame=''>0.022 0 0 0 -0 0</pose>
          <mass>0.01</mass>
          <inertia>
            <ixx>7.89997e-07</ixx>
            <ixy>0</ixy>
            <ixz>0</ixz>
            <iyy>7.89997e-07</iyy>
            <iyz>0</iyz>
            <izz>8e-08</izz>
          </inertia>
        </inertial>
        <collision name='j2n6s300_link_finger_2_collision'>
          <pose frame=''>0 0 0 0 -0 0</pose>
          <geometry>
            <mesh>
              <scale>1 1 1</scale>
              <uri>/home/brian/intern_ws/src/kinova-ros/kinova_description/meshes/finger_proximal.dae</uri>
            </mesh>
          </geometry>
          <max_contacts>10</max_contacts>
          <surface>
            <contact>
              <ode/>
            </contact>
            <bounce/>
            <friction>
              <torsional>
                <ode/>
              </torsional>
              <ode/>
            </friction>
          </surface>
        </collision>
        <visual name='j2n6s300_link_finger_2_visual'>
          <pose frame=''>0 0 0 0 -0 0</pose>
          <geometry>
            <mesh>
              <scale>1 1 1</scale>
              <uri>/home/brian/intern_ws/src/kinova-ros/kinova_description/meshes/finger_proximal.dae</uri>
            </mesh>
          </geometry>
        </visual>
        <self_collide>0</self_collide>
        <kinematic>0</kinematic>
        <gravity>1</gravity>
      </link>
      <joint name='j2n6s300_joint_finger_2' type='revolute'>
        <child>j2n6s300_link_finger_2</child>
        <parent>j2n6s300_link_6</parent>
        <axis>
          <xyz>0.983 -0.183608 0</xyz>
          <limit>
            <lower>0</lower>
            <upper>1.51</upper>
            <effort>2</effort>
            <velocity>1</velocity>
          </limit>
          <dynamics>
            <spring_reference>0</spring_reference>
            <spring_stiffness>0</spring_stiffness>
          </dynamics>
          <use_parent_model_frame>1</use_parent_model_frame>
        </axis>
      </joint>
      <link name='j2n6s300_link_finger_tip_2'>
        <pose frame=''>0.029028 0.127566 0.340112 1.5708 -0.649262 1.38614</pose>
        <inertial>
          <pose frame=''>0.022 0 0 0 -0 0</pose>
          <mass>0.01</mass>
          <inertia>
            <ixx>7.89997e-07</ixx>
            <ixy>0</ixy>
            <ixz>0</ixz>
            <iyy>7.89997e-07</iyy>
            <iyz>0</iyz>
            <izz>8e-08</izz>
          </inertia>
        </inertial>
        <collision name='j2n6s300_link_finger_tip_2_collision'>
          <pose frame=''>0 0 0 0 -0 0</pose>
          <geometry>
            <mesh>
              <scale>1 1 1</scale>
              <uri>/home/brian/intern_ws/src/kinova-ros/kinova_description/meshes/finger_distal.dae</uri>
            </mesh>
          </geometry>
          <max_contacts>10</max_contacts>
          <surface>
            <contact>
              <ode/>
            </contact>
            <bounce/>
            <friction>
              <torsional>
                <ode/>
              </torsional>
              <ode/>
            </friction>
          </surface>
        </collision>
        <visual name='j2n6s300_link_finger_tip_2_visual'>
          <pose frame=''>0 0 0 0 -0 0</pose>
          <geometry>
            <mesh>
              <scale>1 1 1</scale>
              <uri>/home/brian/intern_ws/src/kinova-ros/kinova_description/meshes/finger_distal.dae</uri>
            </mesh>
          </geometry>
        </visual>
        <self_collide>0</self_collide>
        <kinematic>0</kinematic>
        <gravity>1</gravity>
      </link>
      <joint name='j2n6s300_joint_finger_tip_2' type='revolute'>
        <child>j2n6s300_link_finger_tip_2</child>
        <parent>j2n6s300_link_finger_2</parent>
        <axis>
          <xyz>0.983 -0.183608 0</xyz>
          <limit>
            <lower>0</lower>
            <upper>2</upper>
            <effort>2</effort>
            <velocity>1</velocity>
          </limit>
          <dynamics>
            <spring_reference>0</spring_reference>
            <spring_stiffness>0</spring_stiffness>
          </dynamics>
          <use_parent_model_frame>1</use_parent_model_frame>
        </axis>
      </joint>
      <link name='j2n6s300_link_finger_3'>
        <pose frame=''>-0.02226 0.091332 0.315899 1.5708 -0.649262 1.75545</pose>
        <inertial>
          <pose frame=''>0.022 0 0 0 -0 0</pose>
          <mass>0.01</mass>
          <inertia>
            <ixx>7.89997e-07</ixx>
            <ixy>0</ixy>
            <ixz>0</ixz>
            <iyy>7.89997e-07</iyy>
            <iyz>0</iyz>
            <izz>8e-08</izz>
          </inertia>
        </inertial>
        <collision name='j2n6s300_link_finger_3_collision'>
          <pose frame=''>0 0 0 0 -0 0</pose>
          <geometry>
            <mesh>
              <scale>1 1 1</scale>
              <uri>/home/brian/intern_ws/src/kinova-ros/kinova_description/meshes/finger_proximal.dae</uri>
            </mesh>
          </geometry>
          <max_contacts>10</max_contacts>
          <surface>
            <contact>
              <ode/>
            </contact>
            <bounce/>
            <friction>
              <torsional>
                <ode/>
              </torsional>
              <ode/>
            </friction>
          </surface>
        </collision>
        <visual name='j2n6s300_link_finger_3_visual'>
          <pose frame=''>0 0 0 0 -0 0</pose>
          <geometry>
            <mesh>
              <scale>1 1 1</scale>
              <uri>/home/brian/intern_ws/src/kinova-ros/kinova_description/meshes/finger_proximal.dae</uri>
            </mesh>
          </geometry>
        </visual>
        <self_collide>0</self_collide>
        <kinematic>0</kinematic>
        <gravity>1</gravity>
      </link>
      <joint name='j2n6s300_joint_finger_3' type='revolute'>
        <child>j2n6s300_link_finger_3</child>
        <parent>j2n6s300_link_6</parent>
        <axis>
          <xyz>0.983 0.183608 0</xyz>
          <limit>
            <lower>0</lower>
            <upper>1.51</upper>
            <effort>2</effort>
            <velocity>1</velocity>
          </limit>
          <dynamics>
            <spring_reference>0</spring_reference>
            <spring_stiffness>0</spring_stiffness>
          </dynamics>
          <use_parent_model_frame>1</use_parent_model_frame>
        </axis>
      </joint>
      <link name='j2n6s300_link_finger_tip_3'>
        <pose frame=''>-0.029028 0.127566 0.340112 1.5708 -0.649262 1.75545</pose>
        <inertial>
          <pose frame=''>0.022 0 0 0 -0 0</pose>
          <mass>0.01</mass>
          <inertia>
            <ixx>7.89997e-07</ixx>
            <ixy>0</ixy>
            <ixz>0</ixz>
            <iyy>7.89997e-07</iyy>
            <iyz>0</iyz>
            <izz>8e-08</izz>
          </inertia>
        </inertial>
        <collision name='j2n6s300_link_finger_tip_3_collision'>
          <pose frame=''>0 0 0 0 -0 0</pose>
          <geometry>
            <mesh>
              <scale>1 1 1</scale>
              <uri>/home/brian/intern_ws/src/kinova-ros/kinova_description/meshes/finger_distal.dae</uri>
            </mesh>
          </geometry>
          <max_contacts>10</max_contacts>
          <surface>
            <contact>
              <ode/>
            </contact>
            <bounce/>
            <friction>
              <torsional>
                <ode/>
              </torsional>
              <ode/>
            </friction>
          </surface>
        </collision>
        <visual name='j2n6s300_link_finger_tip_3_visual'>
          <pose frame=''>0 0 0 0 -0 0</pose>
          <geometry>
            <mesh>
              <scale>1 1 1</scale>
              <uri>/home/brian/intern_ws/src/kinova-ros/kinova_description/meshes/finger_distal.dae</uri>
            </mesh>
          </geometry>
        </visual>
        <self_collide>0</self_collide>
        <kinematic>0</kinematic>
        <gravity>1</gravity>
      </link>
      <joint name='j2n6s300_joint_finger_tip_3' type='revolute'>
        <child>j2n6s300_link_finger_tip_3</child>
        <parent>j2n6s300_link_finger_3</parent>
        <axis>
          <xyz>0.983 0.183608 0</xyz>
          <limit>
            <lower>0</lower>
            <upper>2</upper>
            <effort>2</effort>
            <velocity>1</velocity>
          </limit>
          <dynamics>
            <spring_reference>0</spring_reference>
            <spring_stiffness>0</spring_stiffness>
          </dynamics>
          <use_parent_model_frame>1</use_parent_model_frame>
        </axis>
      </joint>
      <plugin name='gazebo_ros_control' filename='libgazebo_ros_control.so'>
        <robotNamespace>j2n6s300</robotNamespace>
        <robotSimType>gazebo_ros_control/DefaultRobotHWSim</robotSimType>
        <legacyModeNS>true</legacyModeNS>
      </plugin>
      <plugin name='ft_sensor' filename='libgazebo_ros_ft_sensor.so'>
        <updateRate>30.0</updateRate>
        <topicName>j2n6s300_joint_1_ft_sensor_topic</topicName>
        <jointName>j2n6s300_joint_1</jointName>
        <robotNamespace>/</robotNamespace>
      </plugin>
      <plugin name='ft_sensor' filename='libgazebo_ros_ft_sensor.so'>
        <updateRate>30.0</updateRate>
        <topicName>j2n6s300_joint_2_ft_sensor_topic</topicName>
        <jointName>j2n6s300_joint_2</jointName>
        <robotNamespace>/</robotNamespace>
      </plugin>
      <plugin name='ft_sensor' filename='libgazebo_ros_ft_sensor.so'>
        <updateRate>30.0</updateRate>
        <topicName>j2n6s300_joint_3_ft_sensor_topic</topicName>
        <jointName>j2n6s300_joint_3</jointName>
        <robotNamespace>/</robotNamespace>
      </plugin>
      <plugin name='ft_sensor' filename='libgazebo_ros_ft_sensor.so'>
        <updateRate>30.0</updateRate>
        <topicName>j2n6s300_joint_4_ft_sensor_topic</topicName>
        <jointName>j2n6s300_joint_4</jointName>
        <robotNamespace>/</robotNamespace>
      </plugin>
      <plugin name='ft_sensor' filename='libgazebo_ros_ft_sensor.so'>
        <updateRate>30.0</updateRate>
        <topicName>j2n6s300_joint_5_ft_sensor_topic</topicName>
        <jointName>j2n6s300_joint_5</jointName>
        <robotNamespace>/</robotNamespace>
      </plugin>
      <static>0</static>
      <plugin name='ft_sensor' filename='libgazebo_ros_ft_sensor.so'>
        <updateRate>30.0</updateRate>
        <topicName>j2n6s300_joint_6_ft_sensor_topic</topicName>
        <jointName>j2n6s300_joint_6</jointName>
        <robotNamespace>/</robotNamespace>
      </plugin>
      <pose frame=''>0 0 0 0 -0 0</pose>
    </model>
    <model name='box_1'>
      <link name='link'>
        <pose frame=''>0 0 0 0 -0 0</pose>
        <inertial>
          <mass>1</mass>
          <inertia>
            <ixx>0.166667</ixx>
            <ixy>0</ixy>
            <ixz>0</ixz>
            <iyy>0.166667</iyy>
            <iyz>0</iyz>
            <izz>0.166667</izz>
          </inertia>
          <pose frame=''>0 0 0 0 -0 0</pose>
        </inertial>
        <self_collide>0</self_collide>
        <kinematic>0</kinematic>
        <gravity>1</gravity>
        <visual name='visual'>
          <geometry>
            <box>
              <size>0.4 0.2 0.4</size>
            </box>
          </geometry>
          <material>
            <script>
              <name>Gazebo/Grey</name>
              <uri>file://media/materials/scripts/gazebo.material</uri>
            </script>
            <ambient>0.3 0.3 0.3 1</ambient>
            <diffuse>0.7 0.7 0.7 1</diffuse>
            <specular>0.01 0.01 0.01 1</specular>
            <emissive>0 0 0 1</emissive>
            <shader type='vertex'>
              <normal_map>__default__</normal_map>
            </shader>
          </material>
          <pose frame=''>0 0 0 0 -0 0</pose>
          <cast_shadows>1</cast_shadows>
          <transparency>0</transparency>
        </visual>
        <collision name='collision'>
          <laser_retro>0</laser_retro>
          <max_contacts>10</max_contacts>
          <pose frame=''>0 0 0 0 -0 0</pose>
          <geometry>
            <box>
              <size>0.4 0.2 0.4</size>
            </box>
          </geometry>
          <surface>
            <friction>
              <ode>
                <mu>1</mu>
                <mu2>1</mu2>
                <fdir1>0 0 0</fdir1>
                <slip1>0</slip1>
                <slip2>0</slip2>
              </ode>
              <torsional>
                <coefficient>1</coefficient>
                <patch_radius>0</patch_radius>
                <surface_radius>0</surface_radius>
                <use_patch_radius>1</use_patch_radius>
                <ode>
                  <slip>0</slip>
                </ode>
              </torsional>
            </friction>
            <bounce>
              <restitution_coefficient>0</restitution_coefficient>
              <threshold>1e+06</threshold>
            </bounce>
            <contact>
              <collide_without_contact>0</collide_without_contact>
              <collide_without_contact_bitmask>1</collide_without_contact_bitmask>
              <collide_bitmask>1</collide_bitmask>
              <ode>
                <soft_cfm>0</soft_cfm>
                <soft_erp>0.2</soft_erp>
                <kp>1e+13</kp>
                <kd>1</kd>
                <max_vel>0.01</max_vel>
                <min_depth>0</min_depth>
              </ode>
              <bullet>
                <split_impulse>1</split_impulse>
                <split_impulse_penetration_threshold>-0.01</split_impulse_penetration_threshold>
                <soft_cfm>0</soft_cfm>
                <soft_erp>0.2</soft_erp>
                <kp>1e+13</kp>
                <kd>1</kd>
              </bullet>
            </contact>
          </surface>
        </collision>
      </link>
      <static>0</static>
      <allow_auto_disable>1</allow_auto_disable>
      <pose frame=''>0.185588 -2.21273 0.5 -0 -0 -0</pose>
    </model>
    <model name='box_2'>
      <link name='link'>
        <pose frame=''>0 0 0 0 -0 0</pose>
        <inertial>
          <mass>1</mass>
          <inertia>
            <ixx>0.166667</ixx>
            <ixy>0</ixy>
            <ixz>0</ixz>
            <iyy>0.166667</iyy>
            <iyz>0</iyz>
            <izz>0.166667</izz>
          </inertia>
          <pose frame=''>0 0 0 0 -0 0</pose>
        </inertial>
        <self_collide>0</self_collide>
        <kinematic>0</kinematic>
        <gravity>1</gravity>
        <visual name='visual'>
          <geometry>
            <box>
              <size>0.4 0.2 0.4</size>
            </box>
          </geometry>
          <material>
            <script>
              <name>Gazebo/Grey</name>
              <uri>file://media/materials/scripts/gazebo.material</uri>
            </script>
            <ambient>0.3 0.3 0.3 1</ambient>
            <diffuse>0.7 0.7 0.7 1</diffuse>
            <specular>0.01 0.01 0.01 1</specular>
            <emissive>0 0 0 1</emissive>
            <shader type='vertex'>
              <normal_map>__default__</normal_map>
            </shader>
          </material>
          <pose frame=''>0 0 0 0 -0 0</pose>
          <cast_shadows>1</cast_shadows>
          <transparency>0</transparency>
        </visual>
        <collision name='collision'>
          <laser_retro>0</laser_retro>
          <max_contacts>10</max_contacts>
          <pose frame=''>0 0 0 0 -0 0</pose>
          <geometry>
            <box>
              <size>0.4 0.2 0.4</size>
            </box>
          </geometry>
          <surface>
            <friction>
              <ode>
                <mu>1</mu>
                <mu2>1</mu2>
                <fdir1>0 0 0</fdir1>
                <slip1>0</slip1>
                <slip2>0</slip2>
              </ode>
              <torsional>
                <coefficient>1</coefficient>
                <patch_radius>0</patch_radius>
                <surface_radius>0</surface_radius>
                <use_patch_radius>1</use_patch_radius>
                <ode>
                  <slip>0</slip>
                </ode>
              </torsional>
            </friction>
            <bounce>
              <restitution_coefficient>0</restitution_coefficient>
              <threshold>1e+06</threshold>
            </bounce>
            <contact>
              <collide_without_contact>0</collide_without_contact>
              <collide_without_contact_bitmask>1</collide_without_contact_bitmask>
              <collide_bitmask>1</collide_bitmask>
              <ode>
                <soft_cfm>0</soft_cfm>
                <soft_erp>0.2</soft_erp>
                <kp>1e+13</kp>
                <kd>1</kd>
                <max_vel>0.01</max_vel>
                <min_depth>0</min_depth>
              </ode>
              <bullet>
                <split_impulse>1</split_impulse>
                <split_impulse_penetration_threshold>-0.01</split_impulse_penetration_threshold>
                <soft_cfm>0</soft_cfm>
                <soft_erp>0.2</soft_erp>
                <kp>1e+13</kp>
                <kd>1</kd>
              </bullet>
            </contact>
          </surface>
        </collision>
      </link>
      <static>0</static>
      <allow_auto_disable>1</allow_auto_disable>
      <pose frame=''>-1.37472 0.363348 0.5 0 -0 0</pose>
    </model>
    <model name='to_pickup'>
      <link name='link'>
        <pose frame=''>0 0 0 0 -0 0</pose>
        <inertial>
          <mass>0.0001</mass>
          <inertia>
            <ixx>0.145833</ixx>
            <ixy>0</ixy>
            <ixz>0</ixz>
            <iyy>0.145833</iyy>
            <iyz>0</iyz>
            <izz>0.125</izz>
          </inertia>
          <pose frame=''>0 0 0 0 -0 0</pose>
        </inertial>
        <self_collide>0</self_collide>
        <kinematic>0</kinematic>
        <gravity>1</gravity>
        <visual name='visual'>
          <geometry>
            <box>
              <size>0.02 0.02 0.2</size>
            </box>
          </geometry>
          <material>
            <script>
              <name>Gazebo/Grey</name>
              <uri>file://media/materials/scripts/gazebo.material</uri>
            </script>
            <ambient>0.3 0.3 0.3 1</ambient>
            <diffuse>0.7 0.7 0.7 1</diffuse>
            <specular>0.01 0.01 0.01 1</specular>
            <emissive>0 0 0 1</emissive>
            <shader type='vertex'>
              <normal_map>__default__</normal_map>
            </shader>
          </material>
          <pose frame=''>0 0 0 0 -0 0</pose>
          <cast_shadows>1</cast_shadows>
          <transparency>0</transparency>
        </visual>
        <collision name='collision'>
          <laser_retro>0</laser_retro>
          <max_contacts>10</max_contacts>
          <pose frame=''>0 0 0 0 -0 0</pose>
          <geometry>
            <box>
              <size>0.02 0.02 0.2</size>
            </box>
          </geometry>
          <surface>
            <friction>
              <ode>
                <mu>1</mu>
                <mu2>1</mu2>
                <fdir1>0 0 0</fdir1>
                <slip1>0</slip1>
                <slip2>0</slip2>
              </ode>
              <torsional>
                <coefficient>1</coefficient>
                <patch_radius>0</patch_radius>
                <surface_radius>0</surface_radius>
                <use_patch_radius>1</use_patch_radius>
                <ode>
                  <slip>0</slip>
                </ode>
              </torsional>
            </friction>
            <bounce>
              <restitution_coefficient>0</restitution_coefficient>
              <threshold>1e+06</threshold>
            </bounce>
            <contact>
              <collide_without_contact>0</collide_without_contact>
              <collide_without_contact_bitmask>1</collide_without_contact_bitmask>
              <collide_bitmask>1</collide_bitmask>
              <ode>
                <soft_cfm>0</soft_cfm>
                <soft_erp>0.2</soft_erp>
                <kp>1e+13</kp>
                <kd>1</kd>
                <max_vel>0.01</max_vel>
                <min_depth>0</min_depth>
              </ode>
              <bullet>
                <split_impulse>1</split_impulse>
                <split_impulse_penetration_threshold>-0.01</split_impulse_penetration_threshold>
                <soft_cfm>0</soft_cfm>
                <soft_erp>0.2</soft_erp>
                <kp>1e+13</kp>
                <kd>1</kd>
              </bullet>
            </contact>
          </surface>
        </collision>
      </link>
      <static>0</static>
      <allow_auto_disable>1</allow_auto_disable>
      <pose frame=''>0.499713 -6.3e-05 0.499989 3.8e-05 -3e-06 0.001909</pose>
    </model>
  </world>
</sdf>
